[2025-05-09T16:22:55.362+0100] {taskinstance.py:1956} INFO - Dependencies all met for dep_context=non-requeueable deps ti=<TaskInstance: process_bank_reviews.run_decision_models manual__2025-05-09T15:21:21.879216+00:00 [queued]>
[2025-05-09T16:22:55.370+0100] {taskinstance.py:1956} INFO - Dependencies all met for dep_context=requeueable deps ti=<TaskInstance: process_bank_reviews.run_decision_models manual__2025-05-09T15:21:21.879216+00:00 [queued]>
[2025-05-09T16:22:55.371+0100] {taskinstance.py:2170} INFO - Starting attempt 1 of 2
[2025-05-09T16:22:55.383+0100] {taskinstance.py:2191} INFO - Executing <Task(BashOperator): run_decision_models> on 2025-05-09 15:21:21.879216+00:00
[2025-05-09T16:22:55.389+0100] {standard_task_runner.py:60} INFO - Started process 73148 to run task
[2025-05-09T16:22:55.392+0100] {standard_task_runner.py:87} INFO - Running: ['airflow', 'tasks', 'run', 'process_bank_reviews', 'run_decision_models', 'manual__2025-05-09T15:21:21.879216+00:00', '--job-id', '1886', '--raw', '--subdir', 'DAGS_FOLDER/post_processing.py', '--cfg-path', '/tmp/tmpjjrwpsak']
[2025-05-09T16:22:55.394+0100] {standard_task_runner.py:88} INFO - Job 1886: Subtask run_decision_models
[2025-05-09T16:22:55.444+0100] {task_command.py:423} INFO - Running <TaskInstance: process_bank_reviews.run_decision_models manual__2025-05-09T15:21:21.879216+00:00 [running]> on host DESKTOP-RRUTCI2.
[2025-05-09T16:22:55.529+0100] {taskinstance.py:2480} INFO - Exporting env vars: AIRFLOW_CTX_DAG_OWNER='airflow' AIRFLOW_CTX_DAG_ID='process_bank_reviews' AIRFLOW_CTX_TASK_ID='run_decision_models' AIRFLOW_CTX_EXECUTION_DATE='2025-05-09T15:21:21.879216+00:00' AIRFLOW_CTX_TRY_NUMBER='1' AIRFLOW_CTX_DAG_RUN_ID='manual__2025-05-09T15:21:21.879216+00:00'
[2025-05-09T16:22:55.533+0100] {subprocess.py:63} INFO - Tmp dir root location: /tmp
[2025-05-09T16:22:55.534+0100] {subprocess.py:75} INFO - Running command: ['/usr/bin/bash', '-c', 'cd ~/airflow/dbt_project && dbt run --select decision_schema']
[2025-05-09T16:22:55.543+0100] {subprocess.py:86} INFO - Output:
[2025-05-09T16:23:02.626+0100] {subprocess.py:93} INFO - [0m15:23:02  Running with dbt=1.8.7
[2025-05-09T16:23:03.734+0100] {subprocess.py:93} INFO - [0m15:23:03  Registered adapter: postgres=1.8.2
[2025-05-09T16:23:05.444+0100] {subprocess.py:93} INFO - [0m15:23:05  [[33mWARNING[0m]: Configuration paths exist in your dbt_project.yml file which do not apply to any resources.
[2025-05-09T16:23:05.445+0100] {subprocess.py:93} INFO - There are 1 unused configuration paths:
[2025-05-09T16:23:05.446+0100] {subprocess.py:93} INFO - - models.dbt_project.forPy
[2025-05-09T16:23:05.776+0100] {subprocess.py:93} INFO - [0m15:23:05  Found 8 models, 1 seed, 19 data tests, 2 sources, 540 macros
[2025-05-09T16:23:05.778+0100] {subprocess.py:93} INFO - [0m15:23:05
[2025-05-09T16:23:07.278+0100] {subprocess.py:93} INFO - [0m15:23:07  Concurrency: 3 threads (target='dev')
[2025-05-09T16:23:07.279+0100] {subprocess.py:93} INFO - [0m15:23:07
[2025-05-09T16:23:07.282+0100] {subprocess.py:93} INFO - [0m15:23:07  1 of 5 START sql table model public_decision_schema.dim_bank ................... [RUN]
[2025-05-09T16:23:07.283+0100] {subprocess.py:93} INFO - [0m15:23:07  2 of 5 START sql table model public_decision_schema.dim_branch ................. [RUN]
[2025-05-09T16:23:07.284+0100] {subprocess.py:93} INFO - [0m15:23:07  3 of 5 START sql table model public_decision_schema.dim_location ............... [RUN]
[2025-05-09T16:23:07.464+0100] {subprocess.py:93} INFO - [0m15:23:07  1 of 5 OK created sql table model public_decision_schema.dim_bank .............. [[32mSELECT 3[0m in 0.18s]
[2025-05-09T16:23:07.467+0100] {subprocess.py:93} INFO - [0m15:23:07  4 of 5 START sql table model public_decision_schema.dim_sentiment .............. [RUN]
[2025-05-09T16:23:07.468+0100] {subprocess.py:93} INFO - [0m15:23:07  3 of 5 OK created sql table model public_decision_schema.dim_location .......... [[32mSELECT 14[0m in 0.17s]
[2025-05-09T16:23:07.476+0100] {subprocess.py:93} INFO - [0m15:23:07  5 of 5 START sql table model public_decision_schema.fact_reviews ............... [RUN]
[2025-05-09T16:23:07.477+0100] {subprocess.py:93} INFO - [0m15:23:07  2 of 5 OK created sql table model public_decision_schema.dim_branch ............ [[32mSELECT 14[0m in 0.19s]
[2025-05-09T16:23:07.517+0100] {subprocess.py:93} INFO - [0m15:23:07  4 of 5 OK created sql table model public_decision_schema.dim_sentiment ......... [[32mSELECT 3[0m in 0.05s]
[2025-05-09T16:23:07.773+0100] {subprocess.py:93} INFO - [0m15:23:07  5 of 5 ERROR creating sql table model public_decision_schema.fact_reviews ...... [[31mERROR[0m in 0.30s]
[2025-05-09T16:23:07.785+0100] {subprocess.py:93} INFO - [0m15:23:07
[2025-05-09T16:23:07.787+0100] {subprocess.py:93} INFO - [0m15:23:07  Finished running 5 table models in 0 hours 0 minutes and 2.01 seconds (2.01s).
[2025-05-09T16:23:07.818+0100] {subprocess.py:93} INFO - [0m15:23:07
[2025-05-09T16:23:07.819+0100] {subprocess.py:93} INFO - [0m15:23:07  [31mCompleted with 1 error and 0 warnings:[0m
[2025-05-09T16:23:07.820+0100] {subprocess.py:93} INFO - [0m15:23:07
[2025-05-09T16:23:07.821+0100] {subprocess.py:93} INFO - [0m15:23:07    Database Error in model fact_reviews (models/decision_schema/fact_reviews.sql)
[2025-05-09T16:23:07.821+0100] {subprocess.py:93} INFO -   column "topic_meaning" does not exist
[2025-05-09T16:23:07.822+0100] {subprocess.py:93} INFO -   LINE 21:         topic_meaning,
[2025-05-09T16:23:07.822+0100] {subprocess.py:93} INFO -                    ^
[2025-05-09T16:23:07.823+0100] {subprocess.py:93} INFO -   compiled code at target/run/dbt_project/models/decision_schema/fact_reviews.sql
[2025-05-09T16:23:07.823+0100] {subprocess.py:93} INFO - [0m15:23:07
[2025-05-09T16:23:07.824+0100] {subprocess.py:93} INFO - [0m15:23:07  Done. PASS=4 WARN=0 ERROR=1 SKIP=0 TOTAL=5
[2025-05-09T16:23:08.752+0100] {subprocess.py:97} INFO - Command exited with return code 1
[2025-05-09T16:23:08.763+0100] {taskinstance.py:2698} ERROR - Task failed with exception
Traceback (most recent call last):
  File "/mnt/c/Users/HP/venv/lib/python3.8/site-packages/airflow/models/taskinstance.py", line 433, in _execute_task
    result = execute_callable(context=context, **execute_callable_kwargs)
  File "/mnt/c/Users/HP/venv/lib/python3.8/site-packages/airflow/operators/bash.py", line 212, in execute
    raise AirflowException(
airflow.exceptions.AirflowException: Bash command failed. The command returned a non-zero exit code 1.
[2025-05-09T16:23:08.796+0100] {taskinstance.py:1138} INFO - Marking task as UP_FOR_RETRY. dag_id=process_bank_reviews, task_id=run_decision_models, execution_date=20250509T152121, start_date=20250509T152255, end_date=20250509T152308
[2025-05-09T16:23:08.809+0100] {standard_task_runner.py:107} ERROR - Failed to execute job 1886 for task run_decision_models (Bash command failed. The command returned a non-zero exit code 1.; 73148)
[2025-05-09T16:23:08.847+0100] {local_task_job_runner.py:234} INFO - Task exited with return code 1
[2025-05-09T16:23:08.869+0100] {taskinstance.py:3280} INFO - 0 downstream tasks scheduled from follow-on schedule check
