[2025-05-09T12:00:49.602+0100] {taskinstance.py:1956} INFO - Dependencies all met for dep_context=non-requeueable deps ti=<TaskInstance: scrape_and_insert_bank_reviews.extract_data manual__2025-05-09T10:57:54.626499+00:00 [queued]>
[2025-05-09T12:00:49.616+0100] {taskinstance.py:1956} INFO - Dependencies all met for dep_context=requeueable deps ti=<TaskInstance: scrape_and_insert_bank_reviews.extract_data manual__2025-05-09T10:57:54.626499+00:00 [queued]>
[2025-05-09T12:00:49.617+0100] {taskinstance.py:2170} INFO - Starting attempt 1 of 1
[2025-05-09T12:00:49.646+0100] {taskinstance.py:2191} INFO - Executing <Task(PythonOperator): extract_data> on 2025-05-09 10:57:54.626499+00:00
[2025-05-09T12:00:49.654+0100] {standard_task_runner.py:60} INFO - Started process 4500 to run task
[2025-05-09T12:00:49.661+0100] {standard_task_runner.py:87} INFO - Running: ['airflow', 'tasks', 'run', 'scrape_and_insert_bank_reviews', 'extract_data', 'manual__2025-05-09T10:57:54.626499+00:00', '--job-id', '1876', '--raw', '--subdir', 'DAGS_FOLDER/S_G_M_R.py', '--cfg-path', '/tmp/tmp4kkdd1om']
[2025-05-09T12:00:49.663+0100] {standard_task_runner.py:88} INFO - Job 1876: Subtask extract_data
[2025-05-09T12:00:49.778+0100] {task_command.py:423} INFO - Running <TaskInstance: scrape_and_insert_bank_reviews.extract_data manual__2025-05-09T10:57:54.626499+00:00 [running]> on host DESKTOP-RRUTCI2.
[2025-05-09T12:00:49.972+0100] {taskinstance.py:2480} INFO - Exporting env vars: AIRFLOW_CTX_DAG_OWNER='airflow' AIRFLOW_CTX_DAG_ID='scrape_and_insert_bank_reviews' AIRFLOW_CTX_TASK_ID='extract_data' AIRFLOW_CTX_EXECUTION_DATE='2025-05-09T10:57:54.626499+00:00' AIRFLOW_CTX_TRY_NUMBER='1' AIRFLOW_CTX_DAG_RUN_ID='manual__2025-05-09T10:57:54.626499+00:00'
[2025-05-09T12:00:50.491+0100] {logging_mixin.py:188} INFO - Processing URLs from: https://www.google.com/maps/search/umnia/@33.9861174,-7.0522176,61536m/data=!3m1!1e3!5m1!1e1?entry=ttu&g_ep=EgoyMDI1MDMxMi4wIKXMDSoASAFQAw%3D%3D
[2025-05-09T12:00:50.494+0100] {logging_mixin.py:188} INFO - üîç Scraping de l'URL 1: https://www.google.com/maps/place/Umnia+Bank+Rabat+Hassan/data=!4m7!3m6!1s0xda76ba3de58deff:0xdd1dab642e8baab3!8m2!3d34.0175188!4d-6.8274993!16s%2Fg%2F11h89gp_zr!19sChIJ_95Y3qNrpw0Rs6qLLmSrHd0?authuser=0&hl=fr&rclk=1
[2025-05-09T12:01:08.816+0100] {logging_mixin.py:188} INFO - ‚ö†Ô∏è Could not find bank name for https://www.google.com/maps/place/Umnia+Bank+Rabat+Hassan/data=!4m7!3m6!1s0xda76ba3de58deff:0xdd1dab642e8baab3!8m2!3d34.0175188!4d-6.8274993!16s%2Fg%2F11h89gp_zr!19sChIJ_95Y3qNrpw0Rs6qLLmSrHd0?authuser=0&hl=fr&rclk=1, using default: Umnia Bank
[2025-05-09T12:01:14.082+0100] {logging_mixin.py:188} INFO - Scroll 1: Found 0 new reviews.
[2025-05-09T12:01:17.399+0100] {logging_mixin.py:188} INFO - Scroll 2: Found 8 new reviews.
[2025-05-09T12:01:30.739+0100] {logging_mixin.py:188} INFO - ‚ö†Ô∏è No new reviews loaded after scrolling. Retrying...
[2025-05-09T12:01:41.162+0100] {logging_mixin.py:188} INFO - üîç Scraping de l'URL 2: https://www.google.com/maps/place/Umnia+Bank+Rabat+Al+Manal/data=!4m7!3m6!1s0xda76d82f134b8bb:0x7e069edfb331df78!8m2!3d33.9771289!4d-6.8866143!16s%2Fg%2F11qpt9101m!19sChIJu7g08YJtpw0ReN8xs9-eBn4?authuser=0&hl=fr&rclk=1
[2025-05-09T12:01:58.901+0100] {logging_mixin.py:188} INFO - ‚ö†Ô∏è Could not find bank name for https://www.google.com/maps/place/Umnia+Bank+Rabat+Al+Manal/data=!4m7!3m6!1s0xda76d82f134b8bb:0x7e069edfb331df78!8m2!3d33.9771289!4d-6.8866143!16s%2Fg%2F11qpt9101m!19sChIJu7g08YJtpw0ReN8xs9-eBn4?authuser=0&hl=fr&rclk=1, using default: Umnia Bank
[2025-05-09T12:02:04.175+0100] {logging_mixin.py:188} INFO - Scroll 1: Found 0 new reviews.
[2025-05-09T12:02:07.348+0100] {logging_mixin.py:188} INFO - Scroll 2: Found 10 new reviews.
[2025-05-09T12:02:20.368+0100] {logging_mixin.py:188} INFO - ‚ö†Ô∏è No new reviews loaded after scrolling. Retrying...
[2025-05-09T12:02:30.531+0100] {logging_mixin.py:188} INFO - üîç Scraping de l'URL 3: https://www.google.com/maps/place/Umnia+Bank+Casablanca+Sidi+Maarouf/data=!4m7!3m6!1s0xda62d01956cc4d7:0xbc6d4d9916a571f2!8m2!3d33.5268342!4d-7.6497817!16s%2Fg%2F11sdfzzsht!19sChIJ18RslQEtpg0R8nGlFplNbbw?authuser=0&hl=fr&rclk=1
[2025-05-09T12:02:46.553+0100] {logging_mixin.py:188} INFO - ‚ö†Ô∏è Could not find bank name for https://www.google.com/maps/place/Umnia+Bank+Casablanca+Sidi+Maarouf/data=!4m7!3m6!1s0xda62d01956cc4d7:0xbc6d4d9916a571f2!8m2!3d33.5268342!4d-7.6497817!16s%2Fg%2F11sdfzzsht!19sChIJ18RslQEtpg0R8nGlFplNbbw?authuser=0&hl=fr&rclk=1, using default: Umnia Bank
[2025-05-09T12:02:51.720+0100] {logging_mixin.py:188} INFO - Scroll 1: Found 5 new reviews.
[2025-05-09T12:03:05.251+0100] {logging_mixin.py:188} INFO - ‚ö†Ô∏è No new reviews loaded after scrolling. Retrying...
[2025-05-09T12:03:15.315+0100] {logging_mixin.py:188} INFO - Scroll 2: Found 0 new reviews.
[2025-05-09T12:03:28.330+0100] {logging_mixin.py:188} INFO - ‚ö†Ô∏è No new reviews loaded after scrolling. Retrying...
[2025-05-09T12:03:38.433+0100] {logging_mixin.py:188} INFO - üîç Scraping de l'URL 4: https://www.google.com/maps/place/Umnia+Bank+Mohamedia/data=!4m7!3m6!1s0xda7b764df62e4cf:0x9c1f3b80873a90db!8m2!3d33.6944861!4d-7.3906088!16s%2Fg%2F11g0lb54th!19sChIJz-Ri32S3pw0R25A6h4A7H5w?authuser=0&hl=fr&rclk=1
[2025-05-09T12:03:54.593+0100] {logging_mixin.py:188} INFO - ‚ö†Ô∏è Could not find bank name for https://www.google.com/maps/place/Umnia+Bank+Mohamedia/data=!4m7!3m6!1s0xda7b764df62e4cf:0x9c1f3b80873a90db!8m2!3d33.6944861!4d-7.3906088!16s%2Fg%2F11g0lb54th!19sChIJz-Ri32S3pw0R25A6h4A7H5w?authuser=0&hl=fr&rclk=1, using default: Umnia Bank
[2025-05-09T12:03:59.783+0100] {logging_mixin.py:188} INFO - Scroll 1: Found 4 new reviews.
[2025-05-09T12:04:13.086+0100] {logging_mixin.py:188} INFO - ‚ö†Ô∏è No new reviews loaded after scrolling. Retrying...
[2025-05-09T12:04:23.130+0100] {logging_mixin.py:188} INFO - Scroll 2: Found 0 new reviews.
[2025-05-09T12:04:36.592+0100] {logging_mixin.py:188} INFO - ‚ö†Ô∏è No new reviews loaded after scrolling. Retrying...
[2025-05-09T12:04:46.757+0100] {logging_mixin.py:188} INFO - üîç Scraping de l'URL 5: https://www.google.com/maps/place/Umnia+Bank+Casablanca+Derb+Sultan/data=!4m7!3m6!1s0xda7cd318534e0cd:0x95e9d5712f841b1c!8m2!3d33.5749471!4d-7.6020382!16s%2Fg%2F11q2v_h8ml!19sChIJzeA0hTHNpw0RHBuEL3HV6ZU?authuser=0&hl=fr&rclk=1
[2025-05-09T12:05:03.012+0100] {logging_mixin.py:188} INFO - ‚ö†Ô∏è 'Avis' button not found for Ait lamine Shopping
[2025-05-09T12:05:03.024+0100] {logging_mixin.py:188} INFO - Scroll 1: Found 0 new reviews.
[2025-05-09T12:05:03.034+0100] {logging_mixin.py:188} INFO - ‚ö†Ô∏è Error during scrolling: Message: no such element: Unable to locate element: {"method":"css selector","selector":"div.m6QErb.DxyBCb.kA9KIf.dS8AEf.XiKgde"}
  (Session info: chrome=134.0.6998.88); For documentation on this error, please visit: https://www.selenium.dev/documentation/webdriver/troubleshooting/errors#no-such-element-exception
Stacktrace:
#0 0x555c8486bffa <unknown>
#1 0x555c8432a970 <unknown>
#2 0x555c8437c385 <unknown>
#3 0x555c8437c5b1 <unknown>
#4 0x555c843cb3c4 <unknown>
#5 0x555c843a22bd <unknown>
#6 0x555c843c870c <unknown>
#7 0x555c843a2063 <unknown>
#8 0x555c8436e328 <unknown>
#9 0x555c8436f491 <unknown>
#10 0x555c8483342b <unknown>
#11 0x555c848372ec <unknown>
#12 0x555c8481aa22 <unknown>
#13 0x555c84837e64 <unknown>
#14 0x555c847febef <unknown>
#15 0x555c8485a558 <unknown>
#16 0x555c8485a736 <unknown>
#17 0x555c8486ae76 <unknown>
#18 0x7f06b8cb4609 start_thread
[2025-05-09T12:05:13.241+0100] {logging_mixin.py:188} INFO - ‚ö†Ô∏è No new reviews loaded after scrolling. Retrying...
[2025-05-09T12:05:23.255+0100] {logging_mixin.py:188} INFO - Scroll 2: Found 0 new reviews.
[2025-05-09T12:05:23.268+0100] {logging_mixin.py:188} INFO - ‚ö†Ô∏è Error during scrolling: Message: no such element: Unable to locate element: {"method":"css selector","selector":"div.m6QErb.DxyBCb.kA9KIf.dS8AEf.XiKgde"}
  (Session info: chrome=134.0.6998.88); For documentation on this error, please visit: https://www.selenium.dev/documentation/webdriver/troubleshooting/errors#no-such-element-exception
Stacktrace:
#0 0x555c8486bffa <unknown>
#1 0x555c8432a970 <unknown>
#2 0x555c8437c385 <unknown>
#3 0x555c8437c5b1 <unknown>
#4 0x555c843cb3c4 <unknown>
#5 0x555c843a22bd <unknown>
#6 0x555c843c870c <unknown>
#7 0x555c843a2063 <unknown>
#8 0x555c8436e328 <unknown>
#9 0x555c8436f491 <unknown>
#10 0x555c8483342b <unknown>
#11 0x555c848372ec <unknown>
#12 0x555c8481aa22 <unknown>
#13 0x555c84837e64 <unknown>
#14 0x555c847febef <unknown>
#15 0x555c8485a558 <unknown>
#16 0x555c8485a736 <unknown>
#17 0x555c8486ae76 <unknown>
#18 0x7f06b8cb4609 start_thread
[2025-05-09T12:05:33.478+0100] {logging_mixin.py:188} INFO - ‚ö†Ô∏è No new reviews loaded after scrolling. Retrying...
[2025-05-09T12:05:43.497+0100] {logging_mixin.py:188} INFO - üîç Scraping de l'URL 6: https://www.google.com/maps/place/Umnia+Bank/data=!4m7!3m6!1s0xda62d2d53b1b3ff:0x11b56e12292f3f0!8m2!3d33.5604018!4d-7.6444656!16s%2Fg%2F11hbhfl114!19sChIJ_7OxUy0tpg0R8POSIuFWGwE?authuser=0&hl=fr&rclk=1
[2025-05-09T12:05:59.497+0100] {logging_mixin.py:188} INFO - ‚ö†Ô∏è Could not find bank name for https://www.google.com/maps/place/Umnia+Bank/data=!4m7!3m6!1s0xda62d2d53b1b3ff:0x11b56e12292f3f0!8m2!3d33.5604018!4d-7.6444656!16s%2Fg%2F11hbhfl114!19sChIJ_7OxUy0tpg0R8POSIuFWGwE?authuser=0&hl=fr&rclk=1, using default: Ait lamine Shopping
[2025-05-09T12:06:04.624+0100] {logging_mixin.py:188} INFO - Scroll 1: Found 0 new reviews.
[2025-05-09T12:06:07.810+0100] {logging_mixin.py:188} INFO - Scroll 2: Found 10 new reviews.
[2025-05-09T12:06:20.926+0100] {logging_mixin.py:188} INFO - ‚ö†Ô∏è No new reviews loaded after scrolling. Retrying...
[2025-05-09T12:06:31.087+0100] {logging_mixin.py:188} INFO - üîç Scraping de l'URL 7: https://www.google.com/maps/place/Umnia+Bank+Sal%C3%A9+Hay+Karima/data=!4m7!3m6!1s0xda7697fda31cd91:0x620c198559f1cf30!8m2!3d34.0549942!4d-6.7943047!16s%2Fg%2F11f159g29d!19sChIJkc0x2n9ppw0RMM_xWYUZDGI?authuser=0&hl=fr&rclk=1
[2025-05-09T12:06:47.335+0100] {logging_mixin.py:188} INFO - ‚ö†Ô∏è Could not find bank name for https://www.google.com/maps/place/Umnia+Bank+Sal%C3%A9+Hay+Karima/data=!4m7!3m6!1s0xda7697fda31cd91:0x620c198559f1cf30!8m2!3d34.0549942!4d-6.7943047!16s%2Fg%2F11f159g29d!19sChIJkc0x2n9ppw0RMM_xWYUZDGI?authuser=0&hl=fr&rclk=1, using default: Ait lamine Shopping
[2025-05-09T12:06:52.458+0100] {logging_mixin.py:188} INFO - Scroll 1: Found 0 new reviews.
[2025-05-09T12:06:55.652+0100] {logging_mixin.py:188} INFO - Scroll 2: Found 10 new reviews.
[2025-05-09T12:06:58.251+0100] {local_task_job_runner.py:302} WARNING - State of this instance has been externally set to failed. Terminating instance.
[2025-05-09T12:06:58.255+0100] {process_utils.py:131} INFO - Sending 15 to group 4500. PIDs of all processes in the group: [4509, 4515, 4521, 4524, 4545, 4546, 4603, 4613, 4544, 4500]
[2025-05-09T12:06:58.256+0100] {process_utils.py:86} INFO - Sending the signal 15 to group 4500
[2025-05-09T12:06:58.258+0100] {taskinstance.py:2450} ERROR - Received SIGTERM. Terminating subprocesses.
[2025-05-09T12:06:58.260+0100] {logging_mixin.py:188} INFO - ‚ö†Ô∏è Error during scrolling: Task received SIGTERM signal
[2025-05-09T12:06:58.262+0100] {connectionpool.py:824} WARNING - Retrying (Retry(total=2, connect=None, read=None, redirect=None, status=None)) after connection broken by 'NewConnectionError('<urllib3.connection.HTTPConnection object at 0x7f7a1ce65040>: Failed to establish a new connection: [Errno 111] Connection refused')': /session/1c1d81fd31c9073c66d59e1dd805691a/elements
[2025-05-09T12:06:58.264+0100] {connectionpool.py:824} WARNING - Retrying (Retry(total=1, connect=None, read=None, redirect=None, status=None)) after connection broken by 'NewConnectionError('<urllib3.connection.HTTPConnection object at 0x7f7a1ce65c10>: Failed to establish a new connection: [Errno 111] Connection refused')': /session/1c1d81fd31c9073c66d59e1dd805691a/elements
[2025-05-09T12:06:58.265+0100] {connectionpool.py:824} WARNING - Retrying (Retry(total=0, connect=None, read=None, redirect=None, status=None)) after connection broken by 'NewConnectionError('<urllib3.connection.HTTPConnection object at 0x7f7a1ce82100>: Failed to establish a new connection: [Errno 111] Connection refused')': /session/1c1d81fd31c9073c66d59e1dd805691a/elements
[2025-05-09T12:06:58.267+0100] {logging_mixin.py:188} INFO - ‚ö†Ô∏è No new reviews loaded after scrolling. Retrying...
[2025-05-09T12:06:58.393+0100] {process_utils.py:79} INFO - Process psutil.Process(pid=4521, status='terminated', started='12:00:49') (4521) terminated with exit code None
[2025-05-09T12:06:58.396+0100] {process_utils.py:79} INFO - Process psutil.Process(pid=4603, status='terminated', started='12:00:50') (4603) terminated with exit code None
[2025-05-09T12:06:58.533+0100] {process_utils.py:79} INFO - Process psutil.Process(pid=4544, status='terminated', started='12:00:49') (4544) terminated with exit code None
[2025-05-09T12:06:58.536+0100] {process_utils.py:79} INFO - Process psutil.Process(pid=4545, status='terminated', started='12:00:49') (4545) terminated with exit code None
[2025-05-09T12:06:58.539+0100] {process_utils.py:79} INFO - Process psutil.Process(pid=4524, status='terminated', started='12:00:49') (4524) terminated with exit code None
[2025-05-09T12:06:58.542+0100] {process_utils.py:79} INFO - Process psutil.Process(pid=4546, status='terminated', started='12:00:49') (4546) terminated with exit code None
[2025-05-09T12:06:58.544+0100] {process_utils.py:79} INFO - Process psutil.Process(pid=4515, status='terminated', started='12:00:49') (4515) terminated with exit code None
[2025-05-09T12:06:58.546+0100] {process_utils.py:79} INFO - Process psutil.Process(pid=4613, status='terminated', started='12:00:50') (4613) terminated with exit code None
[2025-05-09T12:07:08.278+0100] {connectionpool.py:824} WARNING - Retrying (Retry(total=2, connect=None, read=None, redirect=None, status=None)) after connection broken by 'NewConnectionError('<urllib3.connection.HTTPConnection object at 0x7f7a1ce823d0>: Failed to establish a new connection: [Errno 111] Connection refused')': /session/1c1d81fd31c9073c66d59e1dd805691a/elements
[2025-05-09T12:07:08.279+0100] {connectionpool.py:824} WARNING - Retrying (Retry(total=1, connect=None, read=None, redirect=None, status=None)) after connection broken by 'NewConnectionError('<urllib3.connection.HTTPConnection object at 0x7f7a1ce82490>: Failed to establish a new connection: [Errno 111] Connection refused')': /session/1c1d81fd31c9073c66d59e1dd805691a/elements
[2025-05-09T12:07:08.280+0100] {connectionpool.py:824} WARNING - Retrying (Retry(total=0, connect=None, read=None, redirect=None, status=None)) after connection broken by 'NewConnectionError('<urllib3.connection.HTTPConnection object at 0x7f7a1ce82580>: Failed to establish a new connection: [Errno 111] Connection refused')': /session/1c1d81fd31c9073c66d59e1dd805691a/elements
[2025-05-09T12:07:08.281+0100] {logging_mixin.py:188} INFO - ‚ö†Ô∏è Error extracting review details: HTTPConnectionPool(host='localhost', port=54139): Max retries exceeded with url: /session/1c1d81fd31c9073c66d59e1dd805691a/elements (Caused by NewConnectionError('<urllib3.connection.HTTPConnection object at 0x7f7a1ce826d0>: Failed to establish a new connection: [Errno 111] Connection refused'))
[2025-05-09T12:07:08.281+0100] {logging_mixin.py:188} INFO - üîç Scraping de l'URL 8: https://www.google.com/maps/place/Umnia+Bank+Temara/data=!4m7!3m6!1s0xda70d7144d20999:0x2af577075284bb52!8m2!3d33.9193443!4d-6.9235373!16s%2Fg%2F11fphjtbq6!19sChIJmQnSRHENpw0RUruEUgd39So?authuser=0&hl=fr&rclk=1
[2025-05-09T12:07:08.282+0100] {connectionpool.py:824} WARNING - Retrying (Retry(total=2, connect=None, read=None, redirect=None, status=None)) after connection broken by 'NewConnectionError('<urllib3.connection.HTTPConnection object at 0x7f7a1ce82940>: Failed to establish a new connection: [Errno 111] Connection refused')': /session/1c1d81fd31c9073c66d59e1dd805691a/url
[2025-05-09T12:07:08.283+0100] {connectionpool.py:824} WARNING - Retrying (Retry(total=1, connect=None, read=None, redirect=None, status=None)) after connection broken by 'NewConnectionError('<urllib3.connection.HTTPConnection object at 0x7f7a1ce82a30>: Failed to establish a new connection: [Errno 111] Connection refused')': /session/1c1d81fd31c9073c66d59e1dd805691a/url
[2025-05-09T12:07:08.284+0100] {connectionpool.py:824} WARNING - Retrying (Retry(total=0, connect=None, read=None, redirect=None, status=None)) after connection broken by 'NewConnectionError('<urllib3.connection.HTTPConnection object at 0x7f7a1ce82b80>: Failed to establish a new connection: [Errno 111] Connection refused')': /session/1c1d81fd31c9073c66d59e1dd805691a/url
[2025-05-09T12:07:08.284+0100] {taskinstance.py:2698} ERROR - Task failed with exception
Traceback (most recent call last):
  File "/mnt/c/Users/HP/venv/lib/python3.8/site-packages/urllib3/connection.py", line 174, in _new_conn
    conn = connection.create_connection(
  File "/mnt/c/Users/HP/venv/lib/python3.8/site-packages/urllib3/util/connection.py", line 95, in create_connection
    raise err
  File "/mnt/c/Users/HP/venv/lib/python3.8/site-packages/urllib3/util/connection.py", line 85, in create_connection
    sock.connect(sa)
ConnectionRefusedError: [Errno 111] Connection refused

During handling of the above exception, another exception occurred:

Traceback (most recent call last):
  File "/mnt/c/Users/HP/venv/lib/python3.8/site-packages/urllib3/connectionpool.py", line 715, in urlopen
    httplib_response = self._make_request(
  File "/mnt/c/Users/HP/venv/lib/python3.8/site-packages/urllib3/connectionpool.py", line 416, in _make_request
    conn.request(method, url, **httplib_request_kw)
  File "/mnt/c/Users/HP/venv/lib/python3.8/site-packages/urllib3/connection.py", line 244, in request
    super(HTTPConnection, self).request(method, url, body=body, headers=headers)
  File "/usr/lib/python3.8/http/client.py", line 1256, in request
    self._send_request(method, url, body, headers, encode_chunked)
  File "/usr/lib/python3.8/http/client.py", line 1302, in _send_request
    self.endheaders(body, encode_chunked=encode_chunked)
  File "/usr/lib/python3.8/http/client.py", line 1251, in endheaders
    self._send_output(message_body, encode_chunked=encode_chunked)
  File "/usr/lib/python3.8/http/client.py", line 1011, in _send_output
    self.send(msg)
  File "/usr/lib/python3.8/http/client.py", line 951, in send
    self.connect()
  File "/mnt/c/Users/HP/venv/lib/python3.8/site-packages/urllib3/connection.py", line 205, in connect
    conn = self._new_conn()
  File "/mnt/c/Users/HP/venv/lib/python3.8/site-packages/urllib3/connection.py", line 186, in _new_conn
    raise NewConnectionError(
urllib3.exceptions.NewConnectionError: <urllib3.connection.HTTPConnection object at 0x7f7a1ce82cd0>: Failed to establish a new connection: [Errno 111] Connection refused

During handling of the above exception, another exception occurred:

Traceback (most recent call last):
  File "/mnt/c/Users/HP/venv/lib/python3.8/site-packages/airflow/models/taskinstance.py", line 433, in _execute_task
    result = execute_callable(context=context, **execute_callable_kwargs)
  File "/mnt/c/Users/HP/venv/lib/python3.8/site-packages/airflow/operators/python.py", line 199, in execute
    return_value = self.execute_callable()
  File "/mnt/c/Users/HP/venv/lib/python3.8/site-packages/airflow/operators/python.py", line 216, in execute_callable
    return self.python_callable(*self.op_args, **self.op_kwargs)
  File "/home/osama/airflow/dags/S_G_M_R.py", line 176, in extract_data
    driver.get(url)
  File "/mnt/c/Users/HP/venv/lib/python3.8/site-packages/selenium/webdriver/remote/webdriver.py", line 393, in get
    self.execute(Command.GET, {"url": url})
  File "/mnt/c/Users/HP/venv/lib/python3.8/site-packages/selenium/webdriver/remote/webdriver.py", line 382, in execute
    response = self.command_executor.execute(driver_command, params)
  File "/mnt/c/Users/HP/venv/lib/python3.8/site-packages/selenium/webdriver/remote/remote_connection.py", line 404, in execute
    return self._request(command_info[0], url, body=data)
  File "/mnt/c/Users/HP/venv/lib/python3.8/site-packages/selenium/webdriver/remote/remote_connection.py", line 428, in _request
    response = self._conn.request(method, url, body=body, headers=headers, timeout=self._client_config.timeout)
  File "/mnt/c/Users/HP/venv/lib/python3.8/site-packages/urllib3/request.py", line 81, in request
    return self.request_encode_body(
  File "/mnt/c/Users/HP/venv/lib/python3.8/site-packages/urllib3/request.py", line 173, in request_encode_body
    return self.urlopen(method, url, **extra_kw)
  File "/mnt/c/Users/HP/venv/lib/python3.8/site-packages/urllib3/poolmanager.py", line 376, in urlopen
    response = conn.urlopen(method, u.request_uri, **kw)
  File "/mnt/c/Users/HP/venv/lib/python3.8/site-packages/urllib3/connectionpool.py", line 827, in urlopen
    return self.urlopen(
  File "/mnt/c/Users/HP/venv/lib/python3.8/site-packages/urllib3/connectionpool.py", line 827, in urlopen
    return self.urlopen(
  File "/mnt/c/Users/HP/venv/lib/python3.8/site-packages/urllib3/connectionpool.py", line 827, in urlopen
    return self.urlopen(
  File "/mnt/c/Users/HP/venv/lib/python3.8/site-packages/urllib3/connectionpool.py", line 799, in urlopen
    retries = retries.increment(
  File "/mnt/c/Users/HP/venv/lib/python3.8/site-packages/urllib3/util/retry.py", line 592, in increment
    raise MaxRetryError(_pool, url, error or ResponseError(cause))
urllib3.exceptions.MaxRetryError: HTTPConnectionPool(host='localhost', port=54139): Max retries exceeded with url: /session/1c1d81fd31c9073c66d59e1dd805691a/url (Caused by NewConnectionError('<urllib3.connection.HTTPConnection object at 0x7f7a1ce82cd0>: Failed to establish a new connection: [Errno 111] Connection refused'))
[2025-05-09T12:07:08.323+0100] {taskinstance.py:1138} INFO - Marking task as FAILED. dag_id=scrape_and_insert_bank_reviews, task_id=extract_data, execution_date=20250509T105754, start_date=20250509T110049, end_date=20250509T110708
[2025-05-09T12:07:08.335+0100] {standard_task_runner.py:107} ERROR - Failed to execute job 1876 for task extract_data (HTTPConnectionPool(host='localhost', port=54139): Max retries exceeded with url: /session/1c1d81fd31c9073c66d59e1dd805691a/url (Caused by NewConnectionError('<urllib3.connection.HTTPConnection object at 0x7f7a1ce82cd0>: Failed to establish a new connection: [Errno 111] Connection refused')); 4500)
[2025-05-09T12:07:08.367+0100] {process_utils.py:79} INFO - Process psutil.Process(pid=4500, status='terminated', exitcode=1, started='12:00:49') (4500) terminated with exit code 1
[2025-05-09T12:07:08.368+0100] {process_utils.py:79} INFO - Process psutil.Process(pid=4509, status='terminated', started='12:00:49') (4509) terminated with exit code None
