[2025-05-19T16:30:05.127+0100] {taskinstance.py:1956} INFO - Dependencies all met for dep_context=non-requeueable deps ti=<TaskInstance: scrape_and_insert_bank_reviews.process_reviews manual__2025-05-19T10:58:39.511715+00:00 [queued]>
[2025-05-19T16:30:05.134+0100] {taskinstance.py:1956} INFO - Dependencies all met for dep_context=requeueable deps ti=<TaskInstance: scrape_and_insert_bank_reviews.process_reviews manual__2025-05-19T10:58:39.511715+00:00 [queued]>
[2025-05-19T16:30:05.135+0100] {taskinstance.py:2170} INFO - Starting attempt 2 of 2
[2025-05-19T16:30:05.146+0100] {taskinstance.py:2191} INFO - Executing <Task(PythonOperator): process_reviews> on 2025-05-19 10:58:39.511715+00:00
[2025-05-19T16:30:05.152+0100] {standard_task_runner.py:60} INFO - Started process 98640 to run task
[2025-05-19T16:30:05.154+0100] {standard_task_runner.py:87} INFO - Running: ['airflow', 'tasks', 'run', 'scrape_and_insert_bank_reviews', 'process_reviews', 'manual__2025-05-19T10:58:39.511715+00:00', '--job-id', '1934', '--raw', '--subdir', 'DAGS_FOLDER/S_G_M_R.py', '--cfg-path', '/tmp/tmpy85wf5n2']
[2025-05-19T16:30:05.156+0100] {standard_task_runner.py:88} INFO - Job 1934: Subtask process_reviews
[2025-05-19T16:30:05.207+0100] {task_command.py:423} INFO - Running <TaskInstance: scrape_and_insert_bank_reviews.process_reviews manual__2025-05-19T10:58:39.511715+00:00 [running]> on host DESKTOP-RRUTCI2.
[2025-05-19T16:30:05.412+0100] {taskinstance.py:2480} INFO - Exporting env vars: AIRFLOW_CTX_DAG_OWNER='airflow' AIRFLOW_CTX_DAG_ID='scrape_and_insert_bank_reviews' AIRFLOW_CTX_TASK_ID='process_reviews' AIRFLOW_CTX_EXECUTION_DATE='2025-05-19T10:58:39.511715+00:00' AIRFLOW_CTX_TRY_NUMBER='2' AIRFLOW_CTX_DAG_RUN_ID='manual__2025-05-19T10:58:39.511715+00:00'
[2025-05-19T16:30:46.603+0100] {taskinstance.py:2698} ERROR - Task failed with exception
Traceback (most recent call last):
  File "/mnt/c/Users/HP/venv/lib/python3.8/site-packages/airflow/models/taskinstance.py", line 433, in _execute_task
    result = execute_callable(context=context, **execute_callable_kwargs)
  File "/mnt/c/Users/HP/venv/lib/python3.8/site-packages/airflow/operators/python.py", line 199, in execute
    return_value = self.execute_callable()
  File "/mnt/c/Users/HP/venv/lib/python3.8/site-packages/airflow/operators/python.py", line 216, in execute_callable
    return self.python_callable(*self.op_args, **self.op_kwargs)
  File "/home/osama/airflow/dags/S_G_M_R.py", line 464, in process_reviews
    engine = create_engine(SQL_ALCHEMY_CONN)
NameError: name 'SQL_ALCHEMY_CONN' is not defined
[2025-05-19T16:30:46.616+0100] {taskinstance.py:1138} INFO - Marking task as FAILED. dag_id=scrape_and_insert_bank_reviews, task_id=process_reviews, execution_date=20250519T105839, start_date=20250519T153005, end_date=20250519T153046
[2025-05-19T16:30:46.633+0100] {standard_task_runner.py:107} ERROR - Failed to execute job 1934 for task process_reviews (name 'SQL_ALCHEMY_CONN' is not defined; 98640)
[2025-05-19T16:30:46.701+0100] {local_task_job_runner.py:234} INFO - Task exited with return code 1
[2025-05-19T16:30:46.730+0100] {taskinstance.py:3280} INFO - 0 downstream tasks scheduled from follow-on schedule check
