[2025-05-19T16:39:26.856+0100] {taskinstance.py:1956} INFO - Dependencies all met for dep_context=non-requeueable deps ti=<TaskInstance: scrape_and_insert_bank_reviews.process_reviews manual__2025-05-19T10:58:39.511715+00:00 [queued]>
[2025-05-19T16:39:26.866+0100] {taskinstance.py:1956} INFO - Dependencies all met for dep_context=requeueable deps ti=<TaskInstance: scrape_and_insert_bank_reviews.process_reviews manual__2025-05-19T10:58:39.511715+00:00 [queued]>
[2025-05-19T16:39:26.867+0100] {taskinstance.py:2170} INFO - Starting attempt 3 of 3
[2025-05-19T16:39:26.890+0100] {taskinstance.py:2191} INFO - Executing <Task(PythonOperator): process_reviews> on 2025-05-19 10:58:39.511715+00:00
[2025-05-19T16:39:26.906+0100] {standard_task_runner.py:60} INFO - Started process 2785 to run task
[2025-05-19T16:39:26.917+0100] {standard_task_runner.py:87} INFO - Running: ['airflow', 'tasks', 'run', 'scrape_and_insert_bank_reviews', 'process_reviews', 'manual__2025-05-19T10:58:39.511715+00:00', '--job-id', '1938', '--raw', '--subdir', 'DAGS_FOLDER/S_G_M_R.py', '--cfg-path', '/tmp/tmp5t6mij4m']
[2025-05-19T16:39:26.926+0100] {standard_task_runner.py:88} INFO - Job 1938: Subtask process_reviews
[2025-05-19T16:39:27.022+0100] {task_command.py:423} INFO - Running <TaskInstance: scrape_and_insert_bank_reviews.process_reviews manual__2025-05-19T10:58:39.511715+00:00 [running]> on host DESKTOP-RRUTCI2.
[2025-05-19T16:39:27.365+0100] {taskinstance.py:2480} INFO - Exporting env vars: AIRFLOW_CTX_DAG_OWNER='airflow' AIRFLOW_CTX_DAG_ID='scrape_and_insert_bank_reviews' AIRFLOW_CTX_TASK_ID='process_reviews' AIRFLOW_CTX_EXECUTION_DATE='2025-05-19T10:58:39.511715+00:00' AIRFLOW_CTX_TRY_NUMBER='3' AIRFLOW_CTX_DAG_RUN_ID='manual__2025-05-19T10:58:39.511715+00:00'
[2025-05-19T16:40:10.666+0100] {taskinstance.py:2698} ERROR - Task failed with exception
Traceback (most recent call last):
  File "/mnt/c/Users/HP/venv/lib/python3.8/site-packages/airflow/models/taskinstance.py", line 433, in _execute_task
    result = execute_callable(context=context, **execute_callable_kwargs)
  File "/mnt/c/Users/HP/venv/lib/python3.8/site-packages/airflow/operators/python.py", line 199, in execute
    return_value = self.execute_callable()
  File "/mnt/c/Users/HP/venv/lib/python3.8/site-packages/airflow/operators/python.py", line 216, in execute_callable
    return self.python_callable(*self.op_args, **self.op_kwargs)
  File "/home/osama/airflow/dags/S_G_M_R.py", line 464, in process_reviews
    engine = create_engine(SQL_ALCHEMY_CONN)
NameError: name 'SQL_ALCHEMY_CONN' is not defined
[2025-05-19T16:40:10.684+0100] {taskinstance.py:1138} INFO - Marking task as FAILED. dag_id=scrape_and_insert_bank_reviews, task_id=process_reviews, execution_date=20250519T105839, start_date=20250519T153926, end_date=20250519T154010
[2025-05-19T16:40:10.706+0100] {standard_task_runner.py:107} ERROR - Failed to execute job 1938 for task process_reviews (name 'SQL_ALCHEMY_CONN' is not defined; 2785)
[2025-05-19T16:40:10.758+0100] {local_task_job_runner.py:234} INFO - Task exited with return code 1
[2025-05-19T16:40:10.786+0100] {taskinstance.py:3280} INFO - 0 downstream tasks scheduled from follow-on schedule check
